Workbook
Name __________________________________________________la2: #N/A
Name ________________________________________________la2: #N/A
Name ________________________________________________la5: #N/A
Name _______________________________________________la2: #N/A
Name ______________________________________________la2: #N/A
Name ______________________________________________la5: #N/A
Name _____________________________________________la2: #N/A
Name _____________________________________________la5: #N/A
Name _____________________________________________pmt2: #N/A
Name ____________________________________________la2: #N/A
Name ____________________________________________la5: #N/A
Name ___________________________________________la2: #N/A
Name ___________________________________________la5: #N/A
Name ___________________________________________new1: '[1]หน้า 1'!$N$2
Name ___________________________________________new2: '[1]หน้า 1'!$N$2
Name ___________________________________________pmt2: #N/A
Name __________________________________________la1: #REF!
Name __________________________________________la1: #REF!
Name __________________________________________la1: #REF!
Name __________________________________________la1: #REF!
Name __________________________________________la1: #REF!
Name __________________________________________la1: #REF!
Name __________________________________________la1: #REF!
Name __________________________________________la2: #N/A
Name __________________________________________la3: #REF!
Name __________________________________________la3: #REF!
Name __________________________________________la3: #REF!
Name __________________________________________la3: #REF!
Name __________________________________________la3: #REF!
Name __________________________________________la3: #REF!
Name __________________________________________la3: #REF!
Name __________________________________________la4: #REF!
Name __________________________________________la4: #REF!
Name __________________________________________la4: #REF!
Name __________________________________________la4: #REF!
Name __________________________________________la5: #N/A
Name __________________________________________new1: '[2]หน้า 1'!$N$2
Name __________________________________________new2: '[2]หน้า 1'!$N$2
Name __________________________________________pmt2: #N/A
Name _________________________________________la1: #REF!
Name _________________________________________la1: #REF!
Name _________________________________________la1: #REF!
Name _________________________________________la1: #REF!
Name _________________________________________la1: #REF!
Name _________________________________________la1: #REF!
Name _________________________________________la1: #REF!
Name _________________________________________la2: #N/A
Name _________________________________________la3: #REF!
Name _________________________________________la3: #REF!
Name _________________________________________la3: #REF!
Name _________________________________________la3: #REF!
Name _________________________________________la3: #REF!
Name _________________________________________la3: #REF!
Name _________________________________________la4: #REF!
Name _________________________________________la4: #REF!
Name _________________________________________la4: #REF!
Name _________________________________________la4: #REF!
Name _________________________________________la5: #N/A
Name _________________________________________new1: '[2]หน้า 1'!$N$2
Name _________________________________________new2: '[2]หน้า 1'!$N$2

Sheet รายละเอียด
M1: รายงานการขออนุมัติสินเชื่อ สำหรับวงเงินเกินกว่า 1-5 ล้านบาท | AD1: ไม่พึงเปิดเผย CONFIDENCIAL ส่วนที่ 1 สำหรับเจ้าหน้าที่ด้านการตลาด
A2: วันที่ | E2: 44034 | U2: ชื่อลูกค้า
A3: เลขที่ AF | K3: เลขทะเบียนลูกค้า | U3: ชื่อกิจการ
A4: สาขา/ เขต/ ฝ่าย | K4: เขต | U4: ประเภทธุรกิจ
A5: ผู้นำเสนอ | U5: ที่ตั้งสถานประกอบการ
A6: ผู้อนุมัติ | U6: เบอร์โทรศัพท์ | Y6: 081-9442384 | AD6: เบอร์มือถือ | AG6: 081-9442384
A8: ประเภทสินเชื่อ | M8: วงเงิน | S8: ภาระหนี้ | Y8: หลักประกัน | AI8: ราคาประเมิน
A11: รวมวงเงินเดิม | M11: =SUM(M9:M10) -> 0 | S11: =SUM(S9:S10) -> 0 | AI11: 0
A12: 1.โครงการปรับปรุงสินเชื่อ SMEs มีสุข ระยะที่ 2
B13: 1.เงินกู้ระยะยาว (F/L) | M13: 4000000 | S13: 0
S14: 0
AI17: 4924000
AI21: 1485000
AI22: 1920960
AR24: =AI21+AI22 -> 3405960 | AW24: 1 | AX24: 3 | AY24: 76
A27: วงเงินที่ขอครั้งนี้
A29: โครงการ SMEs 3D | M29: 4000000
A33: รวมวงเงินที่ขอครั้งนี้ | S33: =S13+S14 -> 0 | AI33: =SUM(AI17:AI24) -> 8329960 | AR33: =#REF!+#REF! -> #REF!
A34: วงเงินที่กลุ่มกิจการในเครือ
A35: - | M35: 0 | S35: 0
A36: วงเงินเดิม. (ในนาม หจก.เจริญกิติ )
A37: 1.โครงการปรับปรุงหลักเกณฑ์โครงการสินเชื่อเพื่อยกระดับเศษฐกิจชุมชุน (LEL)ระยะที่ 4 ตามคำสั่งที่ 94/2564 | M37: 5000000 | Y37: 1.บสย.ค้ำประกันเต็มวงเงิน | AJ37: 0
Y38: 2.บุคคลค้ำประกันเต็มวงเงิน 2 คน ได้แก่
Y39: - นายสุริยา เจริญกิตติศัพท์
Y40: - นางรุ่งรัตน์ เจริญกิติศัพท์
A41: 1. โครงการสินเชื่อสร้างโอกาสเสริมสภาพคล่อง SMEs | M41: 2000000 | S41: 2000000 | Y41: 1.บุคคลค้ำประกันเต็มวงเงิน 2 คน ได้แก่
Y42: - นายสุริยา เจริญกิตติศัพท์
Y43: - นางรุ่งรัตน์ เจริญกิติศัพท์
A51: - | M51: 0 | S51: 0
A52: รวมทั้งหมด | M52: =M11+M33 -> 0 | S52: =S11+S33 -> 0 | AI52: =AI33+AI11 -> 8329960
A53: 2. ข้อมูลธุรกิจ
B54: 2.1 ชื่อผู้บริหารหลัก | G54: นายกมล ย้อยยิ้ม | O54: อายุ | P54: 49 | R54: ปี | S54: สถานะภาพ | W54: โสด | Z54: สมรส | AI54: หย่าร้าง | AL54: หม้าย
B55: 2.1.1 ประสบการณ์ในการทำธุรกิจที่ขอกู้ | K55: 6 | L55: ปี | N55: เดือน | P55: ระยะเวลาดำเนินธุรกิจที่ขอกู้ | V55: 5 | X55: ปี | Z55: เดือน | AB55: (นับจากวันที่จดทะเบียนการค้า หรือเอกสารทางราชการที่ใช้อ้างอิง)
B56: 2.1.2 ประวัติการศึกษาสูงสุดของผู้บริหารหลัก | M56: ต่ำกว่าปริญญาตรี | Q56: ปริญญาตรี | U56: ปริญญาโท | X56: ปริญญาเอก | AA56: คณะ / สาขา
B57: 2.1.3 อธิบายประวัติความเป็นมาของธุรกิจ และคุณสมบัติผู้บริหาร เช่น ประสบการณ์ในการทำธุรกิจ ฐานะ/ความมีชื่อเสียงทางสังคม ที่เอื้อต่อธุรกิจหรือสนับสนุนในการทำธุรกิจ
C58: ความเป็นมืออาชีพ ระยะเวลาการดำเนินธุรกิจ ฐานะทางการเงิน วินัยทางการเงิน เป็นต้น
E59: ประวัติผู้บริหาร
F60: ชื่อ | G60: นายกมล ย้อยยิ้ม | M60: เกิดวันที่ | O60: เกิดวันที่ 29 พฤษภาคม 2517 | U60: อายุ | V60: 49 | W60: ปี | Y60: เลขที่บัตรประชาชน | AD60: 3770300425897
G61: ที่อยู่ทะเบียนบ้าน เลขที่ | M61: 23/12 หมู่ 5 ต.ห้วยยาง อ.ทับสะแก จ.ประจวบคีรีขันธ์
G62: การศึกษา | M62: วิทยาลัยเทคนิคประจวบคีรีขันธ์ สาขาวิชาช่างยนต์
...

Sheet ใบสรุปวงเงิน
C2: ใบสรุปวงเงินสินเชื่อลูกค้าราย บจก.เพชรเกษมฐิติพร
C3: ลำดับ | D3: ประเภทสินเชื่อ | E3: วงเงิน | F3: ภาระหนี้ | G3: อัตราดอกเบี้ย | H3: ระยะเวลากู้ | I3: หลักประกัน/ผู้ค้ำ | J3: สถานะ
C4: สินเชื่อ ธพว.
C5: เดิม
D6: ไม่มี
C14: รวม | E14: =+E7+E11 -> 0 | F14: =+F7+F11 -> 0
C15: ครั้งนี้
C16: 1 | D16: โครงการสินเชื่อ Beyond ติดปีก SME
D17: PN | E17: 3000000 | F17: 0 | G17: ปีที่1-3 Fix 3% | H17: 10 ปี | I17: 1. จดจำนองโฉนดที่ดินเลขที่
G18: ปีที่ 4-10 MLR+1.5% | I18: 19857 ต.ศิลาลอย อ.สามร้อยยอด
I19: จ.ประจวบคีรีขันธ์ เนื้อที่ 1 ไร่
I20: กรรมสิทธิ์ น.ส.ฐิติพร เตชะพันธุ์
I21: 2.บุคคลค้ำประกัน 2 ท่าน
I22: -นายเสมอ จันทร์เทศ
I23: -น.ส.ฐิติพร เตชะพันธุ์
C24: รวม | E24: =+E13+E17 -> 3000000 | F24: =+F13+F17 -> 0
C25: รวมสินเชื่อ ธพว. | E25: =+E14+E24 -> 3000000 | F25: =+F14+F24 -> 0
C26: สินเชื่อ กองทุนฯ
C27: เดิม
D28: ไม่มี
C36: รวมวงเงิน กองทุนฯ | E36: =+E29+E33 -> 0 | F36: =+F29+F33 -> 0
C37: รวมทั้งสิ้น | E37: =+E25+E36 -> 3000000 | F37: =+F25+F36 -> 0

Sheet ภพ 30
A1: หนังสือรับรองการหักภาษี ณ ที่จ่าย (แสดงค่าขนส่ง)
A2: บริษัท เอส ที พี ทับสะแก จำกัด | G2: =+#REF!/30 -> #REF!
A3: ลำดับที่ | B3: เดือน | C3: ยอดขาย SLV
C4: จากระบบ e-Withholding Tax
A5: 1 | B5: 243254 | C5: =604609.81+256276.55 -> 860886.36
A6: 2 | B6: 243285 | C6: =433340.79+498244.37 -> 931585.16
A7: 3 | B7: 243313 | C7: =450864.55+436102.3 -> 886966.85
A8: 4 | B8: 243344 | C8: =540020.68+361543.6 -> 901564.28
A9: 5 | B9: 243374 | C9: =358847.74+278260.22 -> 637107.96
A10: 6 | B10: 243405 | C10: =93.48+54602.93+420985.55+935316.52 -> 1410998.5
A11: 7 | B11: 243435 | C11: =310420.86+277909.94 -> 588330.8
A12: 8 | B12: 243466 | C12: =351884.5+541146.39 -> 893030.89
A13: 9 | B13: 243497 | C13: =441869.06+653923.6 -> 1095792.7
A14: 10 | B14: 243527 | C14: =335475.2+421451.33 -> 756926.53
A15: 11 | B15: 243558 | C15: =355120.27+484604.92+285542.53 -> 1125267.7
A16: 12 | B16: 243588 | C16: =256.61+441161.34+437839.36 -> 879257.31 | G16: 0.01 | H16: =#REF!*G16 -> #REF! | I16: =#REF!-H16 -> #REF!
A17: รวม | C17: =SUM(C5:C16) -> 10967715
A18: รายได้เฉลี่ย/เดือน | C18: =+C17/12 -> 913976.25
A19: รายได้เฉลี่ย/ปี | C19: =C18*12 -> 10967715
A20: บริษัท เพชรเกษมฐิติพร จำกัด | G20: =+#REF!/30 -> #REF!
A21: ภ.พ.30
G22: =+#REF!/30 -> #REF!
A23: ลำดับที่ | B23: เดือน | C23: ยอดขาย | E23: ยอดซื้อ | F23: ภาษี
A24: 1 | B24: 243984 | F24: 0
A25: 2 | B25: 244015 | F25: 0
A26: 3 | B26: 244044 | F26: 0
A27: 4 | B27: 244075 | F27: 0
A28: 5 | B28: 244105
A29: 6 | B29: 244136
A30: 7 | B30: 244166
A31: 8 | B31: 244197
A32: 9 | B32: 244228
A33: 10 | B33: 244258
A34: 11 | B34: 244289
A35: 12 | B35: 244319
A36: รวม | C36: =SUM(C24:C35) -> 0 | E36: =SUM(E24:E35) -> 0 | F36: =SUM(F24:F35) -> 0
A37: รายได้เฉลี่ย/เดือน | C37: =+C36/4 -> 0 | E37: =+E36/4 -> 0 | F37: =+F36/4 -> 0
A41: แบบแสดงรายการภาษีมูลค่าเพิ่ม ภ.พ.30
A42: เดือน | B42: ยอดขาย | C42: ภาษีขาย | D42: ยอดซื้อ | E42: ภาษีซื้อ | F42: ภาษีที่ต้องชำระ
A43: 243984 | B43: 24456301 | C43: 1711941.1 | D43: 24252770 | E43: 1697693.8 | F43: 14247.27
...

Sheet โครงสร้าง
B1: =+'ภพ 30'!A20 -> บริษัท เพชรเกษมฐิติพร จำกัด
B2: โครงสร้างการลงทุน | I2: หน่วย : บาท
B3: รายละเอียดการลงทุน | C3: เงินลงทุนผู้กู้ | D3: กู้สถาบันการเงินอื่น | E3: กู้กองทุนฯ(เดิม) | F3: กู้ ธพว.(เดิม) | G3: กู้กองทุนฯ(ครั้งนี้) | H3: กู้ ธพว.(ครั้งนี้) | I3: รวม
B4: 1.ที่ดิน+สิ่งปลูกสร้าง(ปั้มน้ำมัน) | C4: =+I4-D4 -> 0 | D4: 0 | E4: 0 | F4: 0 | G4: 0 | H4: 0 | I4: =+C15 -> 0 | K4: =1256571+74418+594676+1116472 -> 3042137
B5: 2. ที่ดิน (หลักประกันครั้งนี้) | C5: =+I5-H5-D5-F5-E5 -> 0 | D5: 0 | E5: 0 | F5: 0 | G5: 0 | H5: 0 | I5: 0 | J5: รอประเมิน | K5: 2092193
B6: 3. เครื่องมือเครื่องใช้ | C6: =+I6-H6-D6-F6 -> 164167.31 | E6: 0 | G6: 0 | H6: 0 | I6: =+C24 -> 164167.31 | K6: 2092193
B7: 4. เครื่องใช้สำนักงาน | C7: =+I7-H7-D7-F7 -> 486776.2 | E7: 0 | G7: 0 | H7: 0 | I7: =+C25 -> 486776.2 | K7: 2092193
A8: 2.งานระหว่างก่อสร้าง | B8: 3.ยานพาหนะ | C8: =+I8-D8 -> 0 | I8: =+C27 -> 0
B9: 5. ยานพาหนะ | C9: =+I9-H9-D9-F9 -> 5449467.3 | D9: 0 | E9: 0 | G9: 0 | H9: 0 | I9: =+C26 -> 5449467.3 | K9: 2092193
B10: 6. เงินทุนหมุนเวียน | C10: =I10-H10-G10-F10-E10-D10 -> 390264.32 | D10: 6000000 | E10: 0 | F10: 0 | G10: 0 | H10: 3000000 | I10: =+ความต้องการ!F10 -> 9390264.3
B11: 7. สำรองค่าใช้จ่าย | C11: =I11-H11-G11-F11-E11-D11 -> 0 | D11: 0 | E11: 0 | F11: 0 | G11: 0 | H11: 0 | I11: 0 | K11: =+D10+E10 -> 6000000
B12: รวม | C12: =SUM(C4:C11) -> 6490675.1 | D12: =SUM(D4:D11) -> 6000000 | E12: =SUM(E4:E11) -> 0 | F12: =SUM(F4:F11) -> 0 | G12: =SUM(G4:G11) -> 0 | H12: =SUM(H4:H11) -> 3000000 | I12: =SUM(I4:I11) -> 15490675
B13: D/E Ratio | C13: =+K13/K14 -> 1.3866046 | D13: เท่า | K13: =+H12+G12+F12+E12+D12 -> 9000000
K14: =+C12 -> 6490675.1
B15: 1.ที่ดิน+สปส. | C15: 0 | D15: บาท อ้างอิงงบสรรพากรปี 2567
B16: จากสัญญาให้ใช้สิทธิดำเนินการสถานีบริการ วันที่ 5 สิงหาคม 2567 ระหว่าง บมจ.บางจาก ศรีราชา อนุญาตให้ใช้สิทธิดำเนินการสถานีบริการน้ำมันภายใต้เครื่องหมายการค้า
B17: บางจาก บนเนื้อที่ประมาณ 6-2-0 ไร่ ตั้งอยู่เลขที่ 482 หมู่ 2 ต.วังก์พง อ.ปราณบุรี จ.ประจวบคีรีขันธ์ เพื่อจำหน่ายน้ำมันและสินค้าอื่นๆ
B18: 2.เครื่องจักรและอุปกรณ์ | C18: 0 | D18: บาท อ้างอิงงบสรรพากรปี 2567 และอ้างอิงภาระหนี้เครดิตบูโรในนามผู้กู้ บัญชีลำดับที่ 16 และลำดับที่ 30
C19: 0 | D19: บาท อ้างอิงงบสรรพากรปี 2568
C20: 0 | D20: บาท อ้างอิงงบสรรพากรปี 2569
C21: =SUM(C18:C20) -> 0 | D21: บาท อ้างอิงงบสรรพากรปี 2570
B22: 2. ที่ดินเปล่า (หลักประกันครั้งนี้) | D22: บาท
B23: โฉนดที่ดินเลขที่ 19857 ต.ศิลาลอย อ.สามร้อยยอด จ.ประจวบคีรีขันธ์ เนื้อที่ 1 ไร่ กรรมสิทธิ์ น.ส.ฐิติพร เตชะพันธุ์
B24: 3. เครื่องมือเครื่องใช้ | C24: 164167.31 | D24: บาท อ้างอิงงบสรรพากรปี 2567
B25: 4. เครื่องใช้สำนักงาน | C25: 486776.2 | D25: บาท อ้างอิงงบสรรพากรปี 2567
B26: 5. ยานพาหนะ | C26: 5449467.3 | D26: บาท อ้างอิงงบสรรพากรปี 2567
B27: 3.ยานพาหนะ | D27: บาท
B28: รถที่ใช้ในกิจการจากข้อมูลเครดิต จำนวน 4 คัน
B31: รถขนส่งน้ำมัน ชนิดรถกึ่งพ่วง หมายเลขทะเบียน 81-3987 ประจวบคีรีขันธ์
B32: 6.เงินทุนหมุนเวียน | C32: =+I10 -> 9390264.3 | D32: บาท อ้างอิงภาระหนี้เครดิตบูโรในนามผู้กู้
B33: ประกอบด้วย สินเชื่อ ธ.ไทยพาณิชย์ O/D วงเงิน 6,000,000 บาท
B35: 7. สำรองค่าใช้จ่าย | C35: =+I11 -> 0 | D35: บาท
B36: ครั้งนี้ ผู้กู้ ขอรับการสนับสนุนจาก ธพว. โครงการสินเชื่อ Smile Biz ธุรกิจยิ้มได้(2568) P/N 3,000,000 บาท เพื่อสำรองเป็นค่าใช้จ่ายในการดำเนินธุรกิจ
B37: จากงบสรรพากรปี 2567 ค่าใช้จ่ายในการบริหาร(หักค่าเสื่อมราคา) 9,673,228.90 บาท เฉลี่ยเดือนละ 806,102.40 บาท
B38: สำรองเป็นค่าใช้จ่ายในการดำเนินธุรกิจ คิดเป็นค่าใช้จ่ายในการดำเนินธุรกิจประมาณ 6 เดือน เท่ากับ 4,836,614.40 บาท
B39: เดิมผู้กู้มีสินเชื่อกับ ธพว. โครงการสินเชื่อ Extra Cash สำรองค่าใช้จ่าย วงเงิน 3,000,000 บาท ปัจจุบันเงินต้นคงเหลือ 643,710 บาท

Sheet งบการเงิน
A1: =+'ภพ 30'!A20 -> บริษัท เพชรเกษมฐิติพร จำกัด
A2: งบการเงินงบกำไรขาดทุน
A3: รายการ
B4: ปี 2565 | D4: ปี 2566 | F4: ปี 2567
A5: รายได้จากการขาย | D5: 2.7229906e+08 | E5: =D5/D10 -> 0.99435207 | F5: 2.8068568e+08 | G5: =F5/F10 -> 0.99239378
A6: รายได้จากการให้บริการ | E6: =D6/D11 -> 0 | G6: =+F6/F10 -> 0
A7: รายได้จากการให้เช่า | E7: =D7/D11 -> 0 | G7: =+F7/F10 -> 0
E8: =+D8/D9 -> 0 | G8: =+F8/F10 -> 0
A9: รายได้อื่น | D9: 1546661.2 | E9: =+D9/D10 -> 0.0056479291 | F9: 2151319.2 | G9: =+F9/F10 -> 0.0076062156
A10: รวมรายได้ | D10: =SUM(D5:D9) -> 2.7384572e+08 | E10: 1 | F10: =SUM(F5:F9) -> 2.82837e+08 | G10: 1
A11: ต้นทุนขาย | D11: 2.6424015e+08 | E11: =+D11/D10 -> 0.96492342 | F11: 2.7290535e+08 | G11: =+F11/F10 -> 0.96488558
A12: -ค่าเสื่อมราคา (ต้นทุน)
A13: กำไรขั้นต้น | D13: =D10-D11-D12 -> 9605572.3 | E13: =+D13/D10 -> 0.035076584 | F13: =F10-F11-F12 -> 9931657.4 | G13: =+F13/F10 -> 0.03511442
A14: ค่าใช้จ่ายในการบริหาร | D14: 3248115.8 | E14: =D14/D10 -> 0.011861116 | F14: 3493027.9 | G14: =F14/F10 -> 0.012349968
A15: ค่าใช้จ่ายในการขาย | D15: 4767048.5 | E15: =D15/D11 -> 0.018040591 | F15: 4652994 | G15: =F15/F11 -> 0.017049846 | J15: =+F15+F14-F16 -> 8143616.6 | K15: =+J15/F10 -> 0.028792614
A16: -ค่าเสื่อมราคา (ค่าใช้จ่าย) | D16: 494.72 | E16: =+D16/D10 -> 1.8065647e-06 | F16: 2405.29 | G16: =+F16/F10 -> 8.504156e-06
A17: กำไรก่อนดอกเบี้ยจ่าย และภาษีเงินได้ | D17: =+D13-D14-D15+D16 -> 1590902.8 | E17: =+D17/D10 -> 0.0058094856 | F17: =+F13-F14-F15+F16 -> 1788040.8 | G17: =+F17/F10 -> 0.0063218066
A18: ดอกเบี้ยจ่าย | D18: 243915.99 | E18: =+D18/D10 -> 0.00089070586 | F18: 304329.21 | G18: =+F18/F10 -> 0.001075988
A19: กำไรก่อนภาษีเงินได้ | D19: =+D17-D18 -> 1346986.8 | E19: =+D19/D10 -> 0.0049187798 | F19: =+F17-F18 -> 1483711.6 | G19: =+F19/F10 -> 0.0052458186
A20: ภาษีเงินได้นิติบุคคล | D20: 269298.41 | E20: =+D20/D10 -> 0.00098339462 | F20: 296261.27 | G20: =+F20/F10 -> 0.0010474629
A21: กำไร(ขาดทุน)สุทธิ | D21: =D19-D20 -> 1077688.4 | E21: =+D21/D10 -> 0.0039353851 | F21: =F19-F20 -> 1187450.4 | G21: =+F21/F10 -> 0.0041983557
A23: งบการเงินงบดุล
A24: รายการ | B24: ปี 2565 | D24: ปี 2566 | F24: ปี 2567
A25: สินทรัพย์
A26: สินทรัพย์หมุนเวียน | D26: 9053616.9 | E26: =+D26/D28 -> 0.33959374 | F26: 8967198.4 | G26: =+F26/F28 -> 0.32255627
A27: สินทรัพย์ไม่หมุนเวียน | D27: 17606524 | E27: =+D27/D28 -> 0.66040626 | F27: 18833217 | G27: =+F27/F28 -> 0.67744373
A28: รวมสินทรัพย์ | D28: =SUM(D26:D27) -> 26660141 | E28: 1 | F28: =SUM(F26:F27) -> 27800415 | G28: 1
A29: หนี้สินและส่วนของผู้ถือหุ้น
A30: หนี้สิน
A31: หนี้สินหมุนเวียน | D31: 5497105.5 | E31: =D31/D28 -> 0.20619191 | F31: 5894796.4 | G31: =F31/F28 -> 0.21203987
A32: หนี้สินไม่หมุนเวียน | D32: 2496111.5 | E32: =D32/D28 -> 0.093627094 | F32: 2053649.8 | G32: =F32/F28 -> 0.073871192
A33: รวมหนี้สิน | D33: =SUM(D31:D32) -> 7993217 | E33: =D33/D28 -> 0.29981901 | F33: =SUM(F31:F32) -> 7948446.2 | G33: =F33/F28 -> 0.28591106
A34: ส่วนของผู้เป็นหุ้นส่วน
A35: ทุนจดทะเบียน | D35: 1000000 | E35: =D35/D28 -> 0.037509179 | F35: 1000000 | G35: =F35/F28 -> 0.035970686
A36: กำไร(ขาดทุน)สะสม | D36: 17550663 | E36: =D36/D28 -> 0.65831095 | F36: 18735708 | G36: =F36/F28 -> 0.67393625
A37: รวมส่วนของผู้เป็นหุ้นส่วน | D37: =SUM(D35:D36) -> 18550663 | E37: =+D37/D28 -> 0.69582013 | F37: =SUM(F35:F36) -> 19735708 | G37: =+F37/F28 -> 0.70990694
A38: รวมหนี้สินและส่วนผู้ถือหุ้น | D38: =D33+D37 -> 26543880 | E38: =E33+E37 -> 0.99563913 | F38: =F33+F37 -> 27684154 | G38: =G33+G37 -> 0.995818

Sheet ความต้องการ
A1: =+โครงสร้าง!B1 -> บริษัท เพชรเกษมฐิติพร จำกัด
A2: ความต้องการใช้เงินทุนหมุนเวียน
A3: รายการ | D3: สัดส่วน (%) | E3: ระยะเวลา (วัน) | F3: จำนวนเงิน(บาท) | I3: =ประมาณการ!H11 -> 2.82837e+08
A4: ลูกหนี้การค้า | D4: 0.15 | E4: 45 | F4: =ประมาณการ!N11*D4*E4/365 -> 5168075.2 | H4: =1281360.5+1860+11996+8980+9760+1535+3195+168696+54623+32050+3510+5750+7880+11410+44702+600+12580+3210+2035+11155+7890+10100+61440+1830 -> 1758147.5 | M4: ='[580]สรุปรายรับ-จ่ายภายใน'!P7 -> 39038090
A5: บวก STOCK | D5: 1 | E5: 7 | F5: =+B21 -> 7031000
B6: วัตถุดิบ -ของสด(เนื้อสัตว์ต่างๆ) | I6: =ประมาณการ!H11 -> 2.82837e+08 | M6: =J6 -> 0
B7: -ของแห้ง(เครื่องปรุง บรรจุภัณฑ์) | I7: =ประมาณการ!H11 -> 2.82837e+08 | M7: =J7 -> 0
B8: สินค้าคงเหลือสำเร็จรูป(ลูกชิ้นหมู ไส้กรอก หมูยอ จ๊อ) | I8: =ประมาณการ!H12 -> 2.7290535e+08 | M8: =J8 -> 0
A9: ลบ | B9: เจ้าหนี้การค้า | D9: 1 | E9: 3 | F9: =(+ประมาณการ!L12/12)*D9*0.125 -> 2808810.9 | I9: =ประมาณการ!H12 -> 2.7290535e+08 | M9: =J9 -> 0
A10: เงินหมุนเวียนที่ต้องการทั้งหมด | F10: =+F4+F5-F9 -> 9390264.3 | K10: =5000+10200+10200+14000+13500+4500+2000+500+11800+18800+15450+15900+12250+1800+10200+5000+11100+3200+25000+3500+4500+2200+4000+10000+11400 -> 226000
A11: หัก | B11: เงินกู้เงินทุนหมุนเวียนที่ใช้อยู่เดิม
C12: - เงินกู้ O/D เดิม | F12: 3500000
C13: - P/N ธพว. ครั้งนี้ | F13: 3000000
A14: รวม | F14: =F12+F13 -> 6500000
A15: ความต้องการใช้เงินทุนหมุนเวียนในครั้งนี้ | F15: =F10-F14 -> 2890264.3
A17: ลูกหนี้การค้า | B17: กิจการมีนโยบายขายเชื่อ 15%ของยอดขาย ระยะเวลาเครดิตเฉลี่ยที่ 30-60 วัน
B18: จากรายงานลูกหนี้ ณ 31 กรกฎาคม 2568 สรุปลูกหนี้คงค้างรวม 5,433,626 บาท
B19: สาขาประมาณการลูกหนี้การค้า ระยะเวลาเครดิต 45 วัน
A21: STOCK | B21: =6097000+934000 -> 7031000 | C21: บาท
A36: เจ้าหนี้การค้า | B36: ผู้กู้ซื้อน้ำมันจาก บมจ.บางจาก ศรีราชา สัดส่วน 100% ระยะเวลาเครดติ 3 วัน อ้างอิงจากใบแจ้งหนี้/ใบกำกับภาษี
B37: ชำระเงินโดยการตัดผ่านบัญชีธนาคารอัตโนมัติอ้างอิง Statement ธนาคารไทยพาณิชย์ เลขที่บัญชี 612-300707-6
A39: เงินทุนหมุนเวียน | B39: ครั้งนี้ โครงการสินเชื่อ Beyond ติดปีก SME P/N 3,000,000 บาท เพื่อหมุนเวียนเสริมสภาพคล่องในกิจการ
B40: เดิม ผู้กู้มีสินเชื่อกับ ธ.ไทยพาณิชย์ O/D 6,000,000 บาท เป็นวงเงินในการซื้อน้ำมันกับ บมจ.บางจาก ศรีราชา
B41: พิจารณาจากข้อมูลเครดิตบูโรย้อนหลัง 12 เดือน Utilization เฉลี่ย 3.22 ล้านบาท ครั้งนี้จึงนำมาคำนวณ 3.50 ล้านบาท

Sheet ประมาณการ
A1: ประมาณรายได้กิจการ บริษัท เพชรเกษมฐิติพร จำกัด
A2: รายการ | B2: งบการเงินสรรพากร | L2: ประมาณการ
B3: ปี 2564 | C3: % | D3: ปี 2566 | E3: % | F3: ปี 2566 | G3: % | H3: ปี 2567 | I3: % | J3: ปี 2568 | K3: % | L3: ปี 2568 | M3: % | N3: ปี 2569 | O3: % | P3: ปี 2570 | Q3: %
A4: อัตราการเติบโต | J4: (ภ.พ.30 ม.ค.68-มิ.ย.68)
B5: =งบการเงิน!B5 -> 0 | C5: =+B5/B11 -> #REF! | D5: =+งบการเงิน!D5 -> 2.7229906e+08 | E5: =+D5/D11 -> 1 | F5: 0 | G5: =+F5/F11 -> #DIV/0! | I5: =+H5/H11 -> 0
A6: =+งบการเงิน!A6 -> รายได้จากการให้บริการ | E6: =+D6/D11 -> 0 | I6: =+H6/H11 -> 0
A7: =+งบการเงิน!A7 -> รายได้จากการให้เช่า | D7: =+งบการเงิน!D7 -> 0 | E7: =+D7/D11 -> 0 | I7: =+H7/H11 -> 0
A8: รายได้อื่น | B8: =งบการเงิน!#REF! -> #REF! | C8: =+B8/B11 -> #REF! | E8: =D8/D11 -> 0 | F8: 0 | G8: =F8/F11 -> #DIV/0! | I8: =+H8/H11 -> 0 | J8: 0
A9: รายได้จากการขาย | B9: =งบการเงิน!B8 -> 0 | C9: =+B9/B14 -> #DIV/0! | D9: =+งบการเงิน!D8 -> 0 | E9: =+D9/D14 -> 0 | F9: 0 | G9: =+F9/F14 -> #DIV/0! | H9: 2.8068568e+08 | I9: =+H9/H11 -> 0.99239378
A10: =+งบการเงิน!A9 -> รายได้อื่น | B10: =งบการเงิน!B9 -> 0 | C10: =+B10/B15 -> #DIV/0! | D10: =+งบการเงิน!D9 -> 1546661.2 | E10: =+D10/D15 -> -0.3215311 | F10: 0 | G10: =+F10/F15 -> #DIV/0! | H10: 2151319.2 | I10: =+H10/H11 -> 0.0076062156
A11: รวมรายได้ | B11: =+B5+B8 -> #REF! | C11: 1 | D11: =SUM(D5:D8) -> 2.7229906e+08 | E11: =+C11 -> 1 | F11: =F5 -> 0 | G11: =+E11 -> 1 | H11: =SUM(H5:H10) -> 2.82837e+08 | I11: 1 | J11: =+'ภพ 30'!B49 -> 1.3972944e+08 | K11: =+G11 -> 1 | L11: =+'ภพ 30'!B51 -> 2.7945888e+08 | M11: =+E11 -> 1 | N11: =+L11 -> 2.7945888e+08 | O11: =+G11 -> 1 | P11: =+N11 -> 2.7945888e+08 | Q11: =+Q5 -> 0
A12: ต้นทุนขาย | B12: =งบการเงิน!B11 -> 0 | C12: =B12/B11 -> #REF! | D12: =งบการเงิน!D11 -> 2.6424015e+08 | E12: =D12/D11 -> 0.97040419 | F12: =F11*G12 -> 0 | G12: 0 | H12: 2.7290535e+08 | I12: =+H12/H11 -> 0.96488558 | J12: =+J11*K12 -> 1.3482292e+08 | K12: =+I12 -> 0.96488558 | L12: =+L11*M12 -> 2.6964584e+08 | M12: =+K12 -> 0.96488558 | N12: =+N11*M12 -> 2.6964584e+08 | O12: =+N12/N11 -> 0.96488558 | P12: =P11*Q12 -> 2.6964584e+08 | Q12: =O12 -> 0.96488558
A13: กำไรขั้นต้น | B13: =B11-B12 -> #REF! | C13: =+B13/B11 -> #REF! | D13: =D11-D12 -> 8058911.1 | E13: =D13/D11 -> 0.02959581 | F13: =F11-F12 -> 0 | G13: =F13/F11 -> #DIV/0! | H13: =+H11-H12 -> 9931657.4 | I13: =+H13/H11 -> 0.03511442 | J13: =+J11-J12 -> 4906518.3 | K13: =+J13/J11 -> 0.03511442 | L13: =+L11-L12 -> 9813036.6 | M13: =+L13/L11 -> 0.03511442 | N13: =N11-N12 -> 9813036.6 | O13: =N13/N11 -> 0.03511442 | P13: =+P11-P12 -> 9813036.6 | Q13: =+E13 -> 0.02959581
A14: ค่าใช้จ่ายในการบริหาร | B14: =งบการเงิน!B14 -> 0 | C14: =B14/B11 -> #REF! | D14: =งบการเงิน!D14-D17 -> 3248115.8 | E14: =D14/D11 -> 0.011928487 | F14: =F11*G14 -> 0 | G14: 0 | H14: 3493027.9 | I14: =+H14/H11 -> 0.012349968 | J14: =+J11*K14 -> 1725654.1 | K14: =+I14 -> 0.012349968 | L14: =+L11*M14 -> 3451308.2 | M14: =+K14 -> 0.012349968 | N14: =+L14 -> 3451308.2 | O14: =+N14/N11 -> 0.012349968 | P14: =+N14 -> 3451308.2 | Q14: =O14 -> 0.012349968
A15: ค่าใช้จ่ายในการขาย | B15: =งบการเงิน!B16 -> 0 | C15: =B15/B12 -> #DIV/0! | D15: =งบการเงิน!D16-D18 -> -4810300.6 | E15: =D15/D12 -> -0.018204276 | F15: =F12*G15 -> 0 | G15: 0 | H15: 4652994 | I15: =+H15/H11 -> 0.01645115 | J15: =+J11*K15 -> 2298710 | K15: =+I15 -> 0.01645115 | L15: =+L11*M15 -> 4597420 | M15: =+K15 -> 0.01645115 | N15: =+L15 -> 4597420 | O15: =+N15/N11 -> 0.01645115 | P15: =+N15 -> 4597420 | Q15: =O15 -> 0.01645115
A16: EBITDA | B16: =B13-B14 -> #REF! | C16: =B16/B11 -> #REF! | D16: =D13-D14 -> 4810795.3 | E16: =D16/D11 -> 0.017667323 | F16: =F13-F14 -> 0 | G16: =F16/F11 -> #DIV/0! | H16: =H13-H14-H15 -> 1785635.5 | I16: =+H16/H11 -> 0.0063133024 | J16: =J13-J14-J15 -> 882154.22 | K16: =+J16/J11 -> 0.0063133024 | L16: =+L13-L14-L15 -> 1764308.4 | M16: =+L16/L11 -> 0.0063133024 | N16: =N13-N14-N15 -> 1764308.4 | O16: =N16/N11 -> 0.0063133024 | P16: =P13-P14-P15 -> 1764308.4 | Q16: =P16/P11 -> 0.0063133024
A17: -ค่าเสื่อมราคา(ค่าใช้จ่ายในการบริหาร) | B17: 0 | C17: =B17/B11 -> #REF! | D17: 0 | E17: =D17/D11 -> 0 | N17: =H17 -> 0 | O17: =N17/N11 -> 0 | P17: =H17 -> 0 | Q17: =+I17 -> 0
A18: EBIT | C18: =B18/B13 -> #REF! | D18: =D16-D17 -> 4810795.3 | E18: =D18/D11 -> 0.017667323 | J18: =J16-J17 -> 882154.22 | K18: =+J18/J11 -> 0.0063133024 | N18: =N16-N17 -> 1764308.4 | O18: =N18/N11 -> 0.0063133024 | P18: =P16-P17 -> 1764308.4 | Q18: =+I18 -> 0
A19: ต้นทุนทางการเงิน | B19: =งบการเงิน!B18 -> 0 | C19: =B19/B11 -> #REF! | D19: =งบการเงิน!D18 -> 243915.99 | E19: =D19/D11 -> 0.00089576508 | H19: 0 | I19: 0 | L19: 0 | M19: 0 | N19: 0 | O19: 0 | P19: 0 | Q19: 0
A20: กำไรก่อนภาษีเงินได้ | B20: =B18-B19 -> 0 | C20: =B20/B11 -> #REF! | D20: =D18-D19 -> 4566879.3 | E20: =D20/D11 -> 0.016771557 | H20: =+H16-H19 -> 1785635.5 | I20: =+H20/H11 -> 0.0063133024 | L20: =+L16-L19 -> 1764308.4 | M20: =+L20/L11 -> 0.0063133024 | N20: =N18-N19 -> 1764308.4 | O20: =N20/N11 -> 0.0063133024 | P20: =P18-P19 -> 1764308.4 | Q20: =P20/P11 -> 0.0063133024
A21: ภาษีเงินได้ | B21: =งบการเงิน!B20 -> 0 | C21: =B21/B11 -> #REF! | D21: =งบการเงิน!D20 -> 269298.41 | E21: =D21/D11 -> 0.00098898031 | H21: 0 | I21: 0 | L21: 0 | N21: =N11*O21 -> 0 | O21: 0 | P21: =P11*Q21 -> 0 | Q21: =O21 -> 0
A22: กำไร(ขาดทุน)สุทธิ | B22: =B20-B21 -> 0 | C22: =+B22/B11 -> #REF! | D22: =D20-D21 -> 4297580.9 | E22: =D22/D11 -> 0.015782577 | H22: =+H20-H21 -> 1785635.5 | I22: =+H22/H11 -> 0.0063133024 | L22: =+L20-L21 -> 1764308.4 | M22: =+L22/L11 -> 0.0063133024 | N22: =N18-N19-N21 -> 1764308.4 | O22: =N22/N11 -> 0.0063133024 | P22: =P18-P19-P21 -> 1764308.4 | Q22: =+P22/P11 -> 0.0063133024
A23: EBITDA | L23: =L16 -> 1764308.4 | N23: =N16 -> 1764308.4 | P23: =P16 -> 1764308.4
A24: ชำระหนี้สถาบันการเงิน
A25: -ชำระหนี้ในนามผู้กู้ ตามข้อมูลเครดิตบูโร | B25: 0 | N25: =+L56 -> 0 | P25: =+N25 -> 0
A26: - ชำระหนี้ ธพว.(ครั้งนี้) สินเชื่อ | N26: =+I57 -> 0 | P26: =N26 -> 0
A27: - ชำระหนี้ในนาม ผู้กู้ (ตามเครดิตบูโร) | L27: =+L60 -> 654209.92 | N27: =+L27 -> 654209.92 | P27: =+N27 -> 654209.92
A28: - ชำระหนี้ ธพว.(ครั้งนี้) P/N 3.0 ลบ. | L28: =25625*5 -> 128125 | N28: =25625*12 -> 307500 | P28: =+N28 -> 307500
A29: -ชำระหนี้ในนามกรรมการ (นายเสมอฯ) | L29: =+L62 -> 0 | N29: =+L29 -> 0 | P29: =+N29 -> 0
A30: -ชำระหนี้ในนามกรรมการ (นางฐิติพรฯ) | L30: =+L63 -> 49520.64 | N30: =+L30 -> 49520.64 | P30: =+N30 -> 49520.64
A31: รวมผ่อนชำระหนี้ | B31: =SUM(B25:B29) -> 0 | L31: =SUM(L25:L30) -> 831855.56 | N31: =SUM(N25:N30) -> 1011230.6 | P31: =SUM(P25:P30) -> 1011230.6
A32: คงเหลือ | L32: =L23-L31 -> 932452.87 | M32: =+L32/L11 -> 0.0033366371 | N32: =N23-N31 -> 753077.87 | O32: =+N32/N11 -> 0.0026947717 | P32: =P23-P31 -> 753077.87 | Q32: =+P32/P11 -> 0.0026947717
A33: DSCR (เท่า) | L33: =L23/L31 -> 2.1209312 | N33: =N23/N31 -> 1.7447143 | P33: =P23/P31 -> 1.7447143
A35: ที่มาข้อมูล
A36: 1. รายได้
A37: - จากงบการเงินสรรพากรปี 2567 มีรายได้รวม 282,837,003.26 บาท
A38: - จากแบบแสดงรายการภาษีมูลค่าเพิ่ม ภ.พ.30 เดือน ม.ค.2568 - มิ.ย.2568 มียอดขายรวม 139,729,440.39 บาท เฉลี่ยเดือนละ | M38: 23288240 | O38: บาท
A39: 2. ต้นทุนการขาย
A40: - อ้างอิงต้นทุนขายตามข้อมูล Intra จากฝ่ายบริหารความเสี่ยงเครดิต อัตราส่วนทางการเงินมาตรฐาน จำแนกประเภทธุรกิจตาม ISIC Code 3 Digits ISIC Code C107 การผลิตผลิตภัณฑ์อาหารอื่นๆ
A41: อัตราส่วนกำไรขั้นต้น 25.95% ประมาณครั้งนี้ คำนวณต้นทุนขายที่ 75%ของยอดขาย
...

Sheet เครดิตบูโร
A2: การตรวจสอบเครดิตบูโรของผู้กู้ และกรรมการ / ผู้ค้ำประกัน
B3: 1. ประวัติการติดต่อกับสถาบันการเงิน ในนามผู้กู้ | M3: บริษัท เพชรเกษมฐิติพร จำกัด | W3: ตรวจสอบ ณ.วันที่ | AA3: 244221
A4: สถาบันการเงิน
A5: ลำดับ | D5: ชื่อสถาบันการเงิน | K5: ประเภทสินเชื่อ | R5: วันที่เปิดบัญชี | V5: วงเงิน | Z5: ภาระหนี้ | AD5: ยอดการผ่อนชำระต่อเดือน | AI5: สถานะปัจจุบัน
A6: 1 | D6: ธนาคาร | K6: สินเชื่อเพื่อการพาณิชย์ | R6: 242839 | V6: 3000000 | Z6: 2017167 | AD6: 28200 | AI6: ปกติ
A7: 2 | D7: ธนาคาร | K7: สินเชื่อเพื่อการพาณิชย์ | R7: 243283 | V7: 200000 | Z7: 96351 | AD7: 4100 | AI7: ปกติ
A8: 3 | D8: ธนาคาร | K8: สินเชื่อวงเงินเบิกเกินบัญชี | R8: 235031 | V8: 6000000 | Z8: 3795159 | AD8: =+(Z8*7.025/100)/12 -> 22217.493 | AI8: ปกติ
A12: 7 | AI12: ปกติ
A13: 8 | AI13: ปกติ
A14: 9 | AD14: 0 | AI14: ปกติ
D17: รวม | V17: =SUM(V6:Y16) -> 9200000 | Z17: =SUM(Z6:AC16) -> 5908677 | AD17: =SUM(AD6:AH16) -> 54517.493
A18: รายละเอียดข้อมูลสินเชื่อกองทุน
A19: ลำดับ | D19: สินเชื่อกองทุน | K19: ประเภทสินเชื่อ | R19: วันที่เปิดบัญชี | V19: วงเงิน | Z19: ภาระหนี้ | AD19: ยอดการผ่อนชำระต่อเดือน | AI19: สถานะปัจจุบัน
D20: ไม่พบข้อมูล
D21: รวม | V21: =SUM(V20:V20) -> 0 | Z21: =SUM(Z20:Z20) -> 0 | AD21: =SUM(AD20:AH20) -> 0
A22: รายละเอียดข้อมูลสินเชื่ออื่น ๆ เช่น สินเชื่อนอกระบบ
A23: ลำดับ | D23: แหล่งเงินกู้ | K23: ประเภทสินเชื่อ | R23: วันที่เปิดบัญชี | V23: วงเงิน | Z23: ภาระหนี้ | AD23: ยอดการผ่อนชำระต่อเดือน | AI23: สถานะปัจจุบัน
D24: ไม่พบข้อมูล
D25: รวม
D26: รวมทั้งหมด | V26: =+V17+V21+V25 -> 9200000 | Z26: =+Z17+Z21+Z25 -> 5908677 | AD26: =+AD17+AD21+AD25 -> 54517.493
B29: 2. ประวัติการติดต่อกับสถาบันการเงิน ในนามกรรมการ | Q29: นายเสมอ จันทร์เทศ | W29: ตรวจสอบ ณ.วันที่ | AA29: 244196
A30: สถาบันการเงิน
A31: ลำดับ | D31: ชื่อสถาบันการเงิน | K31: ประเภทสินเชื่อ | R31: วันที่เปิดบัญชี | V31: วงเงิน | Z31: ภาระหนี้ | AD31: ยอดการผ่อนชำระต่อเดือน | AI31: สถานะปัจจุบัน
A32: 1 | D32: ธ.กรุงเทพ | K32: บัตรเครดิต | R32: 243906 | V32: 100000 | Z32: 0 | AD32: 0 | AI32: ปกติ | AR32: 54072.26
A33: 2 | D33: ธ.กรุงเทพ | K33: บัตรเครดิต | R33: 240780 | V33: 100000 | Z33: 0 | AD33: 0 | AI33: ปกติ
A34: 3 | D34: ธ.กรุงเทพ | K34: บัตรเครดิต | R34: 239522 | V34: 100000 | Z34: 0 | AD34: 0 | AI34: ปกติ
A35: 4 | D35: ธ.กรุงเทพ | K35: บัตรเครดิต | R35: 238475 | V35: 100000 | Z35: 0 | AD35: 0 | AI35: ปกติ
A36: 5 | D36: บจก.คาร์ด เอกซ์ | K36: บัตรเครดิต | R36: 241676 | V36: 400000 | Z36: 32901 | AD36: =+Z36*0.08 -> 2632.08 | AI36: ปกติ
A37: 6 | D37: บจก.คาร์ด เอกซ์ | K37: บัตรเครดิต | R37: 236440 | V37: 400000 | Z37: 173 | AD37: 173 | AI37: ปกติ
A38: 7 | D38: บจก.คาร์ด เอกซ์ | K38: บัตรเครดิต | R38: 235343 | V38: 400000 | Z38: 0 | AD38: 0 | AI38: ปกติ
A39: 8 | D39: บจก.คาร์ด เอกซ์ | K39: บัตรเครดิต | R39: 235343 | V39: 400000 | Z39: 252 | AD39: 252 | AI39: ปกติ
A40: 9 | D40: ธ.กสิกรไทย | K40: บัตรเครดิต | R40: 237549 | V40: 528000 | Z40: 6279 | AD40: =+Z40*0.08 -> 502.32 | AI40: ปกติ
A41: 10 | D41: บจก.บัตรกรุงศรีอยุธยา | K41: บัตรเครดิต | R41: 231535 | V41: 195000 | Z41: 6038 | AD41: =+Z41*0.1 -> 603.8 | AI41: ปกติ
A42: 11 | D42: บจก.โลตัสส์ มันนี่ เซอร์วิสเซส | K42: บัตรเครดิต | R42: 240481 | V42: 250000 | Z42: 32937 | AD42: =+Z42*0.1 -> 3293.7 | AI42: ปกติ
A43: 12 | D43: ธ.ยูโอบี | K43: บัตรเครดิต | R43: 242422 | V43: 500000 | Z43: 4440 | AD43: =+Z43*0.08 -> 355.2 | AI43: ปกติ
A44: 13 | AI44: ปกติ
A45: 14 | AI45: ปกติ
A46: 15 | AI46: ปกติ
A47: 16 | AI47: ปกติ
A48: 17 | AI48: ปกติ
...

Sheet Statement
A1: การเคลื่อนไหวทางบัญชี
A2: 1 | B2: ธนาคาร | C2: ไทยพาณิชย์ | E2: สาขา ปราณบุรี
A3: ชื่อบัญชี | B3: บจก.เพชรเกษมฐิติพร | E3: เลขที่บัญชี | F3: 612-300707-6
A4: ประเภทบัญชี | B4: เดินสะพัด | C4: วงเงิน | D4: 6 | E4: ลบ.
A6: เดือน | B6: การหมุนเวียนตลอดเดือน | F6: ยอดเงินคงเหลือ
B7: ถอน | D7: ฝาก
B8: ครั้ง | C8: จำนวนเงิน | D8: ครั้ง | E8: จำนวนเงิน
A9: ยอดยกมา | F9: -2741933.7
A10: 24624 | F10: =F9+E10-C10 -> -2741933.7
A11: 24654 | F11: =F10+E11-C11 -> -2741933.7 | J11: =+F11-C12+E12 -> -2741933.7
A12: 24685 | F12: =F11+E12-C12 -> -2741933.7
A13: 24716 | F13: =F12+E13-C13 -> -2741933.7
A14: 24746 | F14: =F13+E14-C14 -> -2741933.7 | J14: =+C15 -> 24098919 | K14: =+E15/5 -> 4669067.3
A15: 24838 | B15: 24 | C15: 24098919 | D15: 77 | E15: 23345336 | F15: =+E15+F9-C15 -> -3495515.9 | J15: =+J14/5 -> 4819783.7
A16: 24869 | B16: 22 | C16: 22159130 | D16: 70 | E16: 22290447 | F16: =F15+E16-C16 -> -3364199.4
A17: 24898 | B17: 20 | C17: 23814663 | D17: 73 | E17: 23814663 | F17: =F16+E17-C17 -> -3364199.4
A18: 24929 | B18: 22 | C18: 25865672 | D18: 80 | E18: 25585940 | F18: =F17+E18-C18 -> -3643931
A19: 24959 | B19: 20 | C19: 22585998 | D19: 71 | E19: 23665026 | F19: =F18+E19-C19 -> -2564902.9
A20: 24990 | B20: 25 | C20: 27303429 | D20: 82 | E20: 25955992 | F20: =F19+E20-C20 -> -3912340.5
A21: 25020 | B21: 21 | C21: 23604947 | D21: 77 | E21: 23725297 | F21: =F20+E21-C21 -> -3791990.8
A22: รวม | B22: =SUM(B10:B21) -> 154 | C22: =SUM(C10:C21) -> 1.6943276e+08 | D22: =SUM(D10:D21) -> 530 | E22: =SUM(E10:E21) -> 1.683827e+08
A23: เฉลี่ยเดือนละ | B23: =B22/7 -> 22 | C23: =C22/7 -> 24204680 | D23: =D22/7 -> 75.714286 | E23: =+E22/7 -> 24054671
A26: 2 | B26: ธนาคาร | E26: สาขา ประจวบคีรีขันธ์
A27: ชื่อบัญชี | E27: เลขที่บัญชี | F27: 715-6-04428-1
A28: ประเภทบัญชี | B28: ออมทรัพย์ | C28: วงเงิน | D28: 2 | E28: ลบ.
A30: เดือน | B30: การหมุนเวียนตลอดเดือน | F30: ยอดเงินคงเหลือ
B31: ถอน | D31: ฝาก
B32: ครั้ง | C32: จำนวนเงิน | D32: ครั้ง | E32: จำนวนเงิน
A33: ยอดยกมา | H33: =+E23+E47 -> 24054671
A34: 24624 | F34: =F33+E34-C34 -> 0
A35: 24654 | F35: =F34+E35-C35 -> 0 | J35: =+F35-C36+E36 -> 0
A36: 24685 | F36: =F35+E36-C36 -> 0
A37: 24716 | F37: =F36+E37-C37 -> 0
A38: 24746 | F38: =F37+E38-C38 -> 0 | J38: =+C39 -> 0 | K38: =+E39/5 -> 0
A39: 24838 | B39: 0 | C39: 0 | D39: 0 | E39: 0 | F39: =F38+E39-C39 -> 0 | J39: =+J38/5 -> 0
A40: 24869 | F40: =F39+E40-C40 -> 0
A41: 24898 | F41: =F40+E41-C41 -> 0
A42: 24929 | F42: =F41+E42-C42 -> 0
A43: 24959 | F43: =F42+E43-C43 -> 0
A44: 24990 | F44: =F43+E44-C44 -> 0
...

Sheet งบสรรพากร
A1: งบสรรพากร
A2: งบกำไรขาดทุน
A3: บริษัท วรวรรณ โลจิสติกส์ จำกัด
A4: รายได้ | D4: ปี 60 | F4: ปี 61 | H4: ปี 62
A5: รายได้จากการบริการ | D5: 4235043.2 | E5: =+D5/D$7 -> 0.94681528 | F5: 14301639 | G5: =+F5/F$7 -> 0.98975653 | H5: 5142662.4 | I5: =+H5/H$7 -> 0.99999994 | K5: =+D5-F5 -> -10066596 | L5: =+K5/D5 -> -2.3769759
A6: รายได้อื่น | D6: 237891.79 | E6: =+D6/D$7 -> 0.053184719 | F6: 148014.59 | G6: =+F6/F$7 -> 0.01024347 | H6: 0.3 | I6: =+H6/H$7 -> 5.8335539e-08 | K6: =+D6-F6 -> 89877.2 | L6: =+K6/D6 -> 0.37780707
B7: รวมรายได้ | D7: =SUM(D5:D6) -> 4472935 | E7: 1 | F7: =SUM(F5:F6) -> 14449654 | G7: 1 | H7: =SUM(H5:H6) -> 5142662.7 | I7: 1 | K7: =SUM(K5:K6) -> -9976718.6 | L7: =+K7/D7 -> -2.2304636
A8: ต้นุทน
A9: ต้นทุนบริการ | D9: 4118629.7 | E9: =+D9/D7 -> 0.92078908 | F9: 11582518 | G9: =+F9/F7 -> 0.80157756 | H9: =4929330.35-H22 -> 4562362.9 | I9: =+H9/H7 -> 0.88715966
A10: รวมต้นทุน | H10: =SUM(H9:H9) -> 4562362.9 | I10: =+H10/H7 -> 0.88715966 | K10: 86.4 | L10: 8.2
B11: กำไรขั้นต้น | D11: =+D7-D10 -> 4472935 | E11: =+D11/D$7 -> 1 | F11: =+F7-F10 -> 14449654 | G11: =+F11/F$7 -> 1 | H11: =+H7-H10 -> 580299.78 | I11: =+H11/H$7 -> 0.11284034 | K11: 83.1 | L11: 5.8
A12: ค่าใช้จ่ายในการขายและบริหาร | D12: 735328.04 | E12: =+D12/D$7 -> 0.16439498 | F12: 1244684.9 | G12: =+F12/F$7 -> 0.086139425 | H12: =562864.99-H27-H28 -> 432582.02 | I12: =+H12/H$7 -> 0.084116352 | K12: 78.3 | L12: 9.9
B13: รวมค่าใช้จ่าย | H13: =SUM(H12:H12) -> 432582.02 | I13: =+H13/H$7 -> 0.084116352 | K13: =+#REF!/3 -> #REF! | L13: =+#REF!/3 -> #REF!
B14: EBITDA | D14: =+D11-D13 -> 4472935 | E14: =+D14/D$7 -> 1 | F14: =+F11-F13 -> 14449654 | G14: =+F14/F$7 -> 1 | H14: =+H11-H13 -> 147717.76 | I14: =+H14/H$7 -> 0.028723984
A15: ต้นทุนทางการเงิน | D15: 0 | E15: =+D15/D$7 -> 0 | F15: 871406.44 | G15: =+F15/F$7 -> 0.060306389 | H15: 125479.01 | I15: =+H15/H$7 -> 0.024399619
A16: กำไรก่อนดอกเบี้ย/ภาษี | D16: =+D14-D15 -> 4472935 | E16: =+D16/D$7 -> 1 | F16: =+F14-F15 -> 13578247 | G16: =+F16/F$7 -> 0.93969361 | H16: =+H14-H15 -> 22238.75 | I16: =+H16/H$7 -> 0.0043243649
B18: คงเหลือเฉลี่ยต่อเดือน | D18: =+D16/12 -> 372744.58 | F18: =+F16/12 -> 1131520.6 | H18: =+H16/12 -> 1853.2292
A20: รายการหักออก
A21: ค่าเสื่อมในต้นทุนบริการ
A22: -ค่าเสื่อมราคาทรัพย์สิน | D22: 722556.6 | F22: 1005879.1 | H22: 366967.47
B23: รวม | D23: =SUM(D22:D22) -> 722556.6 | F23: =SUM(F22:F22) -> 1005879.1 | H23: =SUM(H22:H22) -> 366967.47
A25: ค่าเสื่อมในค่าใช้จ่ายในการบริหาร
A26: ค่าเสื่อมราคาทรัพย์สิน | F26: 4174.57 | H26: 973.59
B27: รวม | D27: =SUM(D26:D26) -> 0 | F27: =SUM(F26:F26) -> 4174.57 | H27: =SUM(H26:H26) -> 973.59
A28: ค่าใช้จ่ายภาษีอากรต้องห้าม | D28: 610221.49 | F28: 52621.56 | H28: 129309.38
B30: รวมค่าเสื่อม | D30: =+D23+D27 -> 722556.6 | F30: =+F23+F27 -> 1010053.6 | H30: =+H23+H27 -> 367941.06
B31: รวมรายการหักออก | D31: =+D28+D30 -> 1332778.1 | F31: =+F28+F30 -> 1062675.2 | H31: =+H28+H30 -> 497250.44
A36: งบดุล
B37: สินทรัพย์หมุนเวียน | D37: ปี 60 | F37: ปี 61 | H37: ปี 62
A38: เงินสดและรายการเทียบเท่าเงินสด | D38: 194169.47 | E38: =+D38/D$49 -> 0.019049595 | F38: 889789.22 | G38: =+F38/F$49 -> 0.041208382 | H38: 687492.22 | I38: =+H38/H$49 -> 0.025320615
A39: ลูกหนี้การค้า | D39: 728819.38 | E39: =+D39/D$49 -> 0.071503076 | F39: 1318755.9 | G39: =+F39/F$49 -> 0.061074908 | H39: 24854 | I39: =+H39/H$49 -> 0.0009153828
A40: ลูกหนี้อื่น | D40: 7435.62 | E40: =+D40/D$49 -> 0.00072949446 | F40: 92907.73 | G40: =+F40/F$49 -> 0.0043027912 | H40: 669507.44 | I40: =+H40/H$49 -> 0.024658228
A41: เงินให้กู้ยืมระยะสั้นแก่บุคคลที่เกี่ยวข้อง | D41: 0 | E41: =+D41/D$49 -> 0 | F41: 8000000 | G41: =+F41/F$49 -> 0.37050017 | H41: 14000000
A42: สินค้าคงเหลือ | D42: 1797677.5 | E42: =+D42/D$49 -> 0.1763667 | F42: 1880683.5 | G42: =+F42/F$49 -> 0.087099193 | H42: 2082205.6 | I42: =+H42/H$49 -> 0.076688468
A43: สินทรัพย์หมุนเวียนอื่น | D43: 190610.77 | E43: =+D43/D$49 -> 0.018700458 | F43: 1490.45 | G43: =+F43/F$49 -> 6.9026496e-05 | H43: 23356.61 | I43: =+H43/H$49 -> 0.00086023333
B44: รวมสินทรัพย์หมุนเวียน | D44: =SUM(D38:D43) -> 2918712.7 | E44: =+D44/D$49 -> 0.28634932 | F44: =SUM(F38:F43) -> 12183627 | G44: =+F44/F$49 -> 0.56425447 | H44: =SUM(H38:H43) -> 17487416 | I44: =+H44/H$49 -> 0.64406855 | K44: =SUM(H38:H43) -> 17487416
B45: สินทรัพย์ไม่หมุนเวียน
A46: อุปกรณ์ | D46: 7267409.2 | E46: =+D46/D$49 -> 0.71299161 | F46: 9319495.7 | G46: =+F46/F$49 -> 0.43160934 | H46: 9573265.5 | I46: =+H46/H$49 -> 0.35258721
A47: สินทรัพย์ไม่หมุนเวียนอื่น | D47: 6717.72 | E47: =+D47/D$49 -> 0.00065906266 | F47: 89310.57 | G47: =+F47/F$49 -> 0.0041361976 | H47: 90801.02 | I47: =+H47/H$49 -> 0.003344238
B48: รวมสินทรัพย์ไม่หมุนเวียน | D48: =SUM(D46:D47) -> 7274126.9 | E48: =+D48/D$49 -> 0.71365068 | F48: =SUM(F46:F47) -> 9408806.3 | G48: =+F48/F$49 -> 0.43574553 | H48: =SUM(H46:H47) -> 9664066.5 | I48: =+H48/H$49 -> 0.35593145
...

Sheet DSCR (2)
A1: ประมาณการความสามารถในการชำระหนี้
A2: ลูกค้าราย : บริษัท เอส ทับสะแก จำกัด
A3: รายได้-รายจ่าย ปี 2566 | Q3: หน่วย : บาท
A4: รายการ | D4: % | E4: รายได้ ปี 2566 | Q4: รวม | R4: เฉลี่ย/เดือน
E5: ม.ค. | F5: ก.พ. | G5: มี.ค. | H5: เม.ย. | I5: พ.ค. | J5: มิ.ย. | K5: ก.ค. | L5: ส.ค. | M5: ก.ย. | N5: ต.ค. | O5: พ.ย. | P5: ธ.ค.
A6: รายได้
A7: รายได้ | D7: =R7/R8 -> 1 | E7: 1551625.9 | F7: 1976430 | G7: 2771642.8 | H7: 1741789.7 | I7: 2327891 | J7: 1875688.8 | K7: 1461274.3 | L7: 2429924.8 | M7: 1858037.2 | N7: 1193201.7 | O7: 2343483.6 | P7: 1871397.1 | Q7: =SUM(E7:P7) -> 23402387 | R7: =Q7/COUNT(E7:P7) -> 1950198.9 | S7: 1577331.4 | T7: 1342214.6
A8: รายได้รวม | D8: 1 | E8: =SUM(E7:E7) -> 1551625.9 | F8: =SUM(F7:F7) -> 1976430 | G8: =SUM(G7:G7) -> 2771642.8 | H8: =SUM(H7:H7) -> 1741789.7 | I8: =SUM(I7:I7) -> 2327891 | J8: =SUM(J7:J7) -> 1875688.8 | K8: =SUM(K7:K7) -> 1461274.3 | L8: =SUM(L7:L7) -> 2429924.8 | M8: =SUM(M7) -> 1858037.2 | N8: =SUM(N7:N7) -> 1193201.7 | O8: =SUM(O7) -> 2343483.6 | P8: =+P7 -> 1871397.1 | Q8: =+Q7 -> 23402387 | R8: =SUM(R7:R7) -> 1950198.9 | S8: =+S7*90% -> 1419598.3 | T8: =+T7*45 -> 60399655
A9: ต้นทุนขาย | S9: =+S8*45/30 -> 2129397.4 | T9: =+T8/30 -> 2013321.8
A10: ต้นทุนบริการ | D10: =+Q10/Q8 -> 0.25245801 | E10: 619651 | F10: 416600 | G10: 606902 | H10: 652390 | I10: 486950 | J10: 554157 | K10: 284462 | L10: 664258 | M10: 306450 | N10: 496800 | O10: 422700 | P10: 396800 | Q10: =SUM(E10:P10) -> 5908120 | R10: =+Q10/12 -> 492343.33
A11: ต้นทุนขายรวม | D11: =+D10 -> 0.25245801 | E11: =SUM(E10:E10) -> 619651 | F11: =SUM(F10:F10) -> 416600 | G11: =SUM(G10:G10) -> 606902 | H11: =SUM(H10:H10) -> 652390 | I11: =SUM(I10:I10) -> 486950 | J11: =SUM(J10:J10) -> 554157 | K11: =SUM(K10:K10) -> 284462 | L11: =SUM(L10:L10) -> 664258 | ... R11: =SUM(R10:R10) -> 492343.33 | T11: =Q11/Q8 -> 0.25245801
A12: กำไรขั้นต้น | D12: =+Q12/Q8 -> 0.74754199 | E12: =+E8-E11 -> 931974.94 | F12: =+F8-F11 -> 1559830 | G12: =+G8-G11 -> 2164740.8 | H12: =+H8-H11 -> 1089399.7 | I12: =+I8-I11 -> 1840941 | J12: =+J8-J11 -> 1321531.8 | K12: =+K8-K11 -> 1176812.3 | L12: =+L8-L11 -> 1765666.8 | ... R12: =+R8-R11 -> 1457855.6
A13: หัก ค่าใช้จ่ายในการขายและบริหาร
A14: ค่าใช้จ่ายในการขายและบริหาร | D14: =+Q14/Q8 -> 0.57855069 | E14: =1730635.33-E11 -> 1110984.3 | F14: =1456032.66-F11 -> 1039432.7 | G14: =2053624.83-G11 -> 1446722.8 | H14: =2034214.37-H11-92900 -> 1288924.4 | I14: =1624837.05-I11-92900 -> 1044987.1 | J14: =1698574-J11-92900 -> 1051517 | K14: =1067665.36-K11-92900 -> 690303.36 | L14: =2168888.32-L11-92900 -> 1411730.3 | M14: =1436468.43-M11-92900 -> 1037118.4 | N14: =1392997.15-N11-92900 -> 803297.15 | O14: =2000880.51-O11-92900 -> 1485280.5 | P14: =1618869.18-P11-92900 -> 1129169.2 | Q14: =SUM(E14:P14) -> 13539467 | R14: =+Q14/12 -> 1128288.9
A15: EBITDA | D15: =+Q15/Q8 -> 0.1689913 | E15: =+E12-E14 -> -179009.39 | F15: =+F12-F14 -> 520397.34 | G15: =+G12-G14 -> 718018 | H15: =+H12-H14 -> -199524.63 | I15: =+I12-I14 -> 795953.99 | J15: =+J12-J14 -> 270014.79 | K15: =+K12-K14 -> 486508.91 | L15: =+L12-L14 -> 353936.51 | ... R15: =+R12-R14 -> 329566.66
A16: หัก ผ่อนชำระหนี้สถาบันการเงินอื่น
A17: ผ่อนชำระตามเครดิตบูโร - บจก.วรวรรณ โลจิสติกส์ | E17: =+เครดิตบูโร!AD51 -> 7812.1 | F17: =+E17 -> 7812.1 | G17: =+F17 -> 7812.1 | H17: =+G17 -> 7812.1 | I17: =+H17 -> 7812.1 | J17: =+I17 -> 7812.1 | K17: =+J17 -> 7812.1 | L17: =+K17 -> 7812.1 | M17: =+L17 -> 7812.1 | ... P17: =+O17 -> 7812.1 | Q17: =SUM(E17:P17) -> 93745.2 | R17: =+Q17/12 -> 7812.1
A18: ผ่อนชำระตามเครดิตบูโร - นายกมล ย้อยยิ้ม | Q18: =SUM(E18:P18) -> 0 | R18: =+Q18/12 -> 0
A19: ผ่อนชำระ ธพว. - โครงการ | E19: 24700 | F19: =E19 -> 24700 | G19: =F19 -> 24700 | H19: =G19 -> 24700 | I19: =H19 -> 24700 | J19: =I19 -> 24700 | K19: =J19 -> 24700 | L19: =K19 -> 24700 | M19: =L19 -> 24700 | ... P19: =O19 -> 24700 | Q19: =SUM(E19:P19) -> 296400 | R19: =+Q19/12 -> 24700
A20: ผ่อนชำระ ธพว. - โครงการ
A21: รวมภาระหนี้ชำระต่อเดือน | D21: =+R21/R8 -> 0.016671171 | E21: =SUM(E17:E19) -> 32512.1 | F21: =SUM(F17:F19) -> 32512.1 | G21: =SUM(G17:G19) -> 32512.1 | H21: =SUM(H17:H19) -> 32512.1 | I21: =SUM(I17:I19) -> 32512.1 | J21: =SUM(J17:J19) -> 32512.1 | K21: =SUM(K17:K19) -> 32512.1 | L21: =SUM(L17:L19) -> 32512.1 | ... R21: =SUM(R17:R19) -> 32512.1
A22: กำไรก่อนภาษี | D22: =+R22/R8 -> 0.15232013 | E22: =+E15-E21 -> -211521.49 | F22: =+F15-F21 -> 487885.24 | G22: =+G15-G21 -> 685505.9 | H22: =+H15-H21 -> -232036.73 | I22: =+I15-I21 -> 763441.89 | J22: =+J15-J21 -> 237502.69 | K22: =+K15-K21 -> 453996.81 | L22: =+L15-L21 -> 321424.41 | ... R22: =+R15-R21 -> 297054.56
A23: DSCR | R23: =+Q15/Q21 -> 10.136739
Z25: การวิเคราะห์ความสามารถในการชำระหนี้ ของผู้ยื่นกู้อ้างอิงจากอัตรากำไรขั้นต้นและการเติบโตของกลุ่มงานบริหารความเสี่ยง

Sheet ความเห็น
A2: ความเห็น
A3: เห็นควรอนุมัติสินเชื่อโครงการ Beyond ติดปีก SME (คำสั่งที่ 19/2568)
A4: 1. เงินกู้ระยะสั้นตามตั๋วสัญญาใช้เงิน(P/N) วงเงิน 3,000,000 บาท
A5: - วัตถุประสงค์เพื่อเป็นเงินทุนหมุนเวียนในกิจการ
A6: - ระยะเวลากู้ 10 ปี ทบทวนวงเงินทุกปี ระยะเวลาตั๋วแต่ละฉบับไม่เกิน 90 วัน
A7: - อัตราดอกเบี้ย ปีที่ 1-3 Fix 3.00% ต่อปี
B8: ปีที่ 4 เป็นต้นไป MLR+1.50% ต่อปี ปัจจุบัน MLR = 7.1%
A9: - หลักประกัน | C9: 1. จดจำนองโฉนดที่ดินเลขที่ 19857 ต.ศิลาลอย อ.สามร้อยยอด จ.ประจวบคีรีขันธ์ เนื้อที่ 1 ไร่
A10: -โฉนดที่ดินเลขที่ 11262 ต.ทรายทอง อ.บางสะพานน้อย จ.ประจวบคีรีขันธ์ เนื้อที่ 0-1-80 ไร่กรรมสิทธิ์ นายเสน่ห์ สุขบุญรักษา | C10: บสย.ค้ำประกันเต็มวงเงิน
A11: 2. บุคคลค้ำประกันเต็มวงเงิน 2 คน ได้แก่ นายสุทธิเกียรติ สุขบุญรักษา , นายวราพงษ์ สุขบุญรักษา | C11: บสย.ค้ำประกันเต็มวงเงิน
C12: กรรมสิทธิ์ น.ส.ฐิติพร เตชะพันธุ์
C13: 2. บุคคลค้ำประกัน 2 ท่าน ได้แก่ นายเสมอ จันทร์เทศ , น.ส.ฐิติพร เตชะพันธุ์
A14: - เงื่อนไขการเบิกจ่าย ให้มีเอกสารด้านการซื้อน้ำมัน ได้แก่ ใบกำกับภาษี หรือใบเสร็จรับเงิน ประกอบการเบิกจ่าย
A16: 2. เงินกู้ระยะยาว (F/L) วงเงิน 1.40 ล้านบาท
A17: - วัตถุประสงค์เพื่อสมทบซื้อเครื่องตู้อบรมควัน 1 เครื่อง
A18: - ระยะเวลากู้ 7 ปี
A19: - อัตราดอกเบี้ย ปีที่ 1-2 MLR-2.75% ต่อปี ปีที่3 เป็นต้นไป MLR+0.75%ต่อปี ปัจจุบัน MLR = 7.25%
B20: ปีที่ 4 เป็นต้นไป MLR+1.50% ต่อปี
A21: - หลักประกัน | C21: - บสย.ค้ำประกันเต็มวงเงิน
A22: -โฉนดที่ดินเลขที่ 11262 ต.ทรายทอง อ.บางสะพานน้อย จ.ประจวบคีรีขันธ์ เนื้อที่ 0-1-80 ไร่กรรมสิทธิ์ นายเสน่ห์ สุขบุญรักษา | C22: บสย.ค้ำประกันเต็มวงเงิน
A23: 2. บุคคลค้ำประกันเต็มวงเงิน 2 คน ได้แก่ นายสุทธิเกียรติ สุขบุญรักษา , นายวราพงษ์ สุขบุญรักษา | C23: บสย.ค้ำประกันเต็มวงเงิน
C24: - บุคคลค้ำประกัน 3 ท่าน ได้แก่ น.ส.ปุณยสรณ์ สิรนันทนาวัฒน์ , น.ส.ภิดาพรรธน์ สิรนันทนาวัฒน์
C25: นายวีรนันท์ สิรนันทนาวัฒน์
C26: -ให้จดทะเบียนเครื่องจักรเป็นหลักประกันทางธุรกิจ
A27: - เงื่อนไขการเบิกจ่าย ให้มีเอกสารใบเสนอราคา และใบวางบิล หรือใบแจ้งหนี้ พร้อมภาพถ่ายเครื่องจักรประกอบการเบิกจ่าย
A29: ลำดับ | B29: รายการเครื่องจักร | G29: ออกเอง | H29: กู้ธพว. | I29: รวม | J29: สัดส่วน
A30: 1 | B30: ตู้อบรมควัน : TL-111-1S จำนวน 1 เครื่อง กำลังการผลิต 150กก./ครั้ง | J30: =+H30/I30 -> #DIV/0!
B31: ตามใบเสนอราคา ลงวันที่ 28 มิ.ย.2568 เลขที่ B250617-03Rev.01
B32: จาก บจก.ทะเลเทคโนโลยี
A34: เหตุผลสนับสนุน
A35: -ผู้กู้ บจก.เพชรเกษมฐิติพร จดทะเบียนเป็นนิติบุคคลเมื่อวันที่ 3 พ.ค.2538 ทะเบียนนิติบุคคลเลขที่ 0775538000226 ทุนจดทะเบียน 1,000,000 บาท
A36: ประกอบธุรกิจสถานีบริการน้ำมันบางจาก การถือหุ้น
B37: ชื่อผู้ถือหุ้น | D37: สัดส่วนหุ้น | E37: มูลค่าหุ้น | F37: อำนาจลงนาม | G37: เงื่อนไข
B38: น.ส.ฐิติพร เตชะพันธุ์ | D38: 0.5 | E38: 500000 | F38: P | G38: กรรมการหนึ่งคนลงลายมือชื่อ | L38: 5000000
B39: นายเสมอ จันทร์เทศ | D39: 0.45 | E39: 450000 | F39: P | G39: และประทับตราบริษัท | L39: 400000 | M39: =+L39/L38 -> 0.08
B40: นางสุมา เพ็ญรัตนา | D40: 0.05 | E40: 50000 | F40: ไม่มี
B41: รวมหุ้น | D41: =SUM(D38:D40) -> 1 | E41: =SUM(E38:E40) -> 1000000
A43: -ผู้กู้มีประสบการณ์ในการประกอบกิจการสถานีบริการน้ำมันมากว่า 30 ปี ปัจจุบันบริหารงานสถานีบริการน้ำมัน 48 หัวจ่าย มีพนักงาน 15 คน
A44: -จากสัญญาให้ใช้สิทธิดำเนินการสถานีบริการ วันเริ่มสัญญา 1 ก.ย.2567 วันสิ้นสุดสัญญา 31 ส.ค.2568 ระหว่างบมจ.บางจาก ศรีราชา(ผู้ให้ใช้สิทธิ)
A45: กับ บจก.เพชรเกษมฐิติพร(ผู้ใช้สิทธิ) อนุญาตให้ใช้สิทธิ ดำเนินการสถานีบริการน้ำมันภายใต้เครื่องหมายการค้าบางจาก บนเนื้อที่ 6-2-0 ไร่
...

Sheet ประวัติกิจการ
A2: ประวัติผู้บริหาร
A3: ชื่อ | B3: ห้างหุ้นส่วนจำกัด บางสะพานชาร์โคล
A4: จดทะเบียน | B4: 240197
A5: ทุนจดทะเบียน | B5: 5,000,000 บาท
A6: สำนักงาน | B6: เลขที่ 555 หมู่ 3 ต.ชัยเกษม อ.บางสะพาน จ.ประจวบคีรีขันธ์
A7: กรรมการ | B7: นายสุทธิเกียรติ สุขบุญรักษา
A8: การถือหุ้น
B9: ชื่อ-สกุล | C9: หุ้น | D9: สัดส่วน % | E9: หมายเหตุ
B10: 1.นายสุทธิเกียรติ สุขบุญรักษา | C10: 2250000 | D10: =+C10/C13 -> 0.45 | E10: หุ้นส่วนผู้จัดการ
B11: 2.นายวราพงษ์ สุขบุญรักษา | C11: 2250000 | D11: 0.45 | E11: หุ้นส่วน
B12: 3.น.ส.วริยา สระสำราญ | C12: 500000 | D12: 0.1 | E12: หุ้นส่วน
B13: รวมมูลค่าหุ้น | C13: =SUM(C10:C12) -> 5000000 | D13: =SUM(D10:D12) -> 1
A15: ประว้ติผู้บริหาร
A16: ชื่อ | B16: นายเสมอ จันทร์เทศ
A17: วันเดือนปี(เกิด) | B17: 23474
A18: อายุ(ปี) | B18: 61 ปี
A19: สถานะภาพ | B19: โสด
A20: เลขที่บัตรประชาชน | B20: 3 7606 00386 46 3
A21: ที่อยู่ตามบัตรประชาชน | B21: 63/2 หมู่ 2 ต.เขาน้อย อ.ปราณบุรี จ.ประจวบคีรีขันธ์
A22: ที่อยู่ตามทะเบียนบ้าน | B22: 63/2 หมู่ 2 ต.เขาน้อย อ.ปราณบุรี จ.ประจวบคีรีขันธ์
A23: สถานะภาพ | B23: สมรส
A24: ประวัติการศึกษา | B24: ปริญญาตรี คณะนิติศาสตร์ มหาวิทยาลัยรามคำแหง
A26: ประสบการทำงาน
A27: ปี 2538 - ปัจจุบัน | B27: กรรมการผู้จัดการ บจก.เพชรเกษมฐิติพร
A28: ปี 2552 - ปัจจุบัน | B28: หุ้นส่วนผู้จัดการ หจก.ธนัญธรฐิติพร
A31: ชื่อ | B31: น.ส.ฐิติพร เตชะพันธุ์
A32: วันเดือนปี(เกิด) | B32: 23143
A33: อายุ(ปี) | B33: 62 ปี
A34: สถานะภาพ | B34: โสด
A35: เลขที่บัตรประชาชน | B35: 3 5199 00002 47 4
A36: ที่อยู่ตามบัตรประชาชน | B36: 50 ถ.อินทยงยศ ต.ในเมือง อ.เมือวบำพูน จ.ลำพูน
A37: ที่อยู่ตามทะเบียนบ้าน | B37: 50 ถ.อินทยงยศ ต.ในเมือง อ.เมือวบำพูน จ.ลำพูน
A38: สถานะภาพ | B38: สมรส
A39: ประวัติการศึกษา | B39: ปริญญาตรี คณะนิติศาสตร์ มหาวิทยาลัยรามคำแหง
A41: ประสบการทำงาน
A42: ปี 2538 - ปัจจุบัน | B42: กรรมการผู้จัดการ บจก.เพชรเกษมฐิติพร

Sheet ผู้ขายผู้ซื้อ
A1: 1. รายชื่อผู้ขายวัตถุดิบ / Supplier
B2: ชื่อผู้ขายวัตถุดิบ / Supplier รายใหญ่ | F2: ประเภทวัตถุดิบ/สินค้า | I2: %ต่อยอดซื้อรวม | K2: เครดิต(วัน) | L2: ระยะเวลาการติดต่อ (ปี)
B3: 1. บมจ.บางจาก ศรีราชา | F3: น้ำมัน | I3: 1 | K3: 3 วัน | L3: 5 ปี
F7: รวม | I7: =SUM(I3:I6) -> 1
A9: 2. รายชื่อลูกค้า(ผู้ซื้อ)รายใหญ่
B10: ชื่อลูกค้า(ผู้ซื้อ)รายใหญ่ | F10: ประเภทวัตถุดิบ/สินค้า | I10: %ต่อยอดขายรวม | K10: เครดิต(วัน) | L10: ระยะเวลาการติดต่อ (ปี)
B11: 1 บจก.สรวีย์ คอนกรีต | F11: น้ำมัน | I11: 0.4 | K11: 30 วัน | L11: 14 ปี
B12: 2. หจก.โชคอนันต์ชัย | F12: น้ำมัน | I12: 0.2 | K12: 30 วัน | L12: 14 ปี
B13: 3. บจก.เอสซีจี ดิสทริบิวชั่น | F13: น้ำมัน | I13: 0.1 | K13: 30 วัน | L13: 14 ปี
B14: 4. ลูกค้าพื้นที่จังหวัดประจวบคีรีขันธ์ | F14: น้ำมัน | I14: 0.3 | K14: เงินสด | L14: 14 ปี
B15: 5. ผู้ใช้รถทั่วไป | F15: น้ำมัน | K15: เงินสด
F16: รวม | I16: =SUM(I11:I15) -> 1

Sheet Sheet2
D2: 1. ความจุถังเก็บรักษาน้ำมันเชื้อเพลิงใต้พื้นดิน
D4: 1. ดีเซล | I4: ความจุ | K4: 100000 | N4: ลิตร | P4: ราคาทุนต่อลิตร | T4: 29.19 | X4: บาท | Z4: สต็อคเต็มถัง | AD4: =+K4*T4 -> 2919000 | AI4: บาท
D5: 2. ดีเซลพลัส | I5: ความจุ | K5: 20000 | N5: ลิตร | P5: ราคาทุนต่อลิตร | T5: 42.26 | X5: บาท | Z5: สต็อคเต็มถัง | AD5: =+K5*T5 -> 845200 | AI5: บาท
D6: 3. แก๊สโซฮอล์ 95 | I6: ความจุ | K6: 40000 | N6: ลิตร | P6: ราคาทุนต่อลิตร | T6: 29.76 | X6: บาท | Z6: สต็อคเต็มถัง | AD6: =+K6*T6 -> 1190400 | AI6: บาท
D7: 4. แก๊สโซฮอล์ 91 | I7: ความจุ | K7: 20000 | N7: ลิตร | P7: ราคาทุนต่อลิตร | T7: 29.42 | X7: บาท | Z7: สต็อคเต็มถัง | AD7: =+K7*T7 -> 588400 | AI7: บาท
D8: 5. แก๊สโซฮอล์E20 | I8: ความจุ | K8: 20000 | N8: ลิตร | P8: ราคาทุนต่อลิตร | T8: 27.7 | X8: บาท | Z8: สต็อคเต็มถัง | AD8: =+K8*T8 -> 554000 | AI8: บาท
D9: 6. น้ำมันหล่อลื่น | I9: ความจุ | K9: 2000 | N9: ลิตร | P9: ราคาทุนต่อลิตร | T9: 0 | X9: บาท | Z9: สต็อคเต็มถัง | AD9: =+K9*T9 -> 0 | AI9: บาท
D10: รวมปริมาณความจุ | K10: =SUM(K4:M9) -> 202000 | N10: ลิตร | AD10: =SUM(AD4:AH8) -> 6097000 | AI10: บาท
D12: 2. ความจุถังเก็บรักษาน้ำมันเชื้อเพลิงรถขนส่งน้ำมัน ชนิดรถกึ่งพ่วง
D13: 1. หมายเลขทะเบียน 81-3987 ประจวบคีรีขันธ์ ปริมาตรรวม 32,000 ลิตร สมุติฐานเก็บน้ำมัน ดีเซล ราคาทุนต่อลิตร 29.19 บาท
D14: สต็อคน้ำมันเต็มถังรถ | K14: 934000 | N14: บาท
D16: (อ้างอิงราคาทุนต่อลิตรตามบิลซื้อ ใบแจ้งหนี้/ใบกำกับภาษี จาก บริษัท บางจาก ศรีราชา จำกัด(มหาชน))
